Workbook

Sheet Code list on site
B1: COCO V6 2nd round Trial Plan(Pilot Line) | F1: 试验登记申请
C3: Date
C4: Code | F4: Code 1 | G4: Code 2 | H4: Code 3 | I4: Code 4-1 | J4: Code 4-2 | K4: Code 5-1 | L4: Code 5-2 | M4: Code 6 | N4: Code 7 | O4: Code 8 | P4: Code 9 | Q4: Code 10
C5: Code Design: | H5: Same With Code 2 | I5: Same With Code 2 | J5: Same With Code 2 | K5: Same With Code 2 | L5: Same With Code 2
C6: SAM: Nuoer 511
C7: LSN: 14126684 - WJ WKRH0C38-P, 38gsm, 200mm
C8: PSN: 14126435 - WJ WK26-P Spunlace, 26gsm, 130mm
C9: REL: 14120936 - ND055, 40gsm, 115mm
C10: Adh: 14112526 - DM2820U
C11: SAM Add on - LSS | F11: 7.75 | G11: 7.75 | H11: =H18*(H16-H17)/1000000/2 -> 6.8817437 | I11: 6 | J11: 7 | K11: 9 | L11: 10 | M11: 7.75 | N11: 7.75 | O11: 7.75 | P11: 8.1 | Q11: 7.75 | R11: control密度 | S11: =8.1/365/120*1000000*2 -> 369.86301
C12: SAM Add on - PSS | F12: 7.75 | G12: 7.75 | H12: =H11 -> 6.8817437 | I12: 6 | J12: 7 | K12: 9 | L12: 10 | M12: 7.75 | N12: 7.75 | O12: 7.75 | P12: 8.1 | Q12: 7.75
C13: Adh - Adh for each layer | F13: 14gsm | G13: 14gsm | H13: TBD | I13: TBD | J13: TBD | M13: 14gsm | N13: 14gsm | O13: 14gsm | P13: 14gsm | Q13: 14gsm | R13: 维持add on不变密度 | S13: =8.1/135/365*1000000*2 -> 328.76712 | T13: =S13/2 -> 164.38356
C14: Channel layer
C15: Channel Area (CAD Area) | F15: =F17/F16 -> 0.059120872 | G15: =G17/G16 -> 0.12263297 | H15: =G15 -> 0.12263297 | I15: =D15 -> 0 | J15: =I15 -> 0 | K15: =#REF! -> #REF! | L15: =K15 -> #REF! | M15: =M17/M16 -> 0.11732905 | N15: =N17/N16 -> 0.097911354 | O15: =O17/O16 -> 0.11434287 | S15: =S13*135*382/1000000 -> 16.954521 | T15: =8.1/365*382*2 -> 16.954521
F16: 40594.8 | G16: 40594.8 | H16: 40594.8 | I16: 40594.8 | J16: 40594.8 | K16: 40595.8 | L16: 40596.8 | M16: 42429.909 | N16: =M16 -> 42429.909 | O16: =N16 -> 42429.909 | P16: 40232.653
F17: =8*300 -> 2400 | G17: 4978.261 | H17: =G17 -> 4978.261 | I17: =H17 -> 4978.261 | J17: =I17 -> 4978.261 | K17: =J17 -> 4978.261 | L17: =K17 -> 4978.261 | M17: =L17 -> 4978.261 | N17: 4154.3698 | O17: =N17+697.1878 -> 4851.5576 | S17: =S15/382*365 -> 16.2 | T17: =T15/382/135*1000000 -> 328.76712
C18: SAM Density | F18: =(F11+F12)/(F16-F17)*1000000 -> 405.8144 | G18: =(G11+G12)/(G16-G17)*1000000 -> 435.19107 | H18: 386.43528 | I18: =I11/(I16-I17)*1000000*2 -> 336.92212 | J18: =J11/(J16-J17)*1000000*2 -> 393.07581 | K18: =K11/(K16-K17)*1000000*2 -> 505.36899 | L18: =L11/(L16-L17)*1000000*2 -> 561.50534
C19: Remark | F19: 浆板8mm
F20: + Middle Bonding
C21: Purpose | F21: If side channel can help improve absorption time | H21: Sam density same with X pad | I21: LSL SAM Add on | K21: USL SAM Add on | M21: bigger area in front pad | N21: shorter center channel | O21: adding a horizontal channel at front | P21: T5.6 Insert 145mm, ：365mm*120mm,16.2
B22: KEY CHANGES
C23: Channel Pattern | F23: Pattern Change | G23: Pattern Change | H23: SAM add on change | M23: Shape change | N23: Pattern Change | O23: Pattern Change | P23: Pad Length
C24: Channel postion
C25: - the front edge of upper layer to pad edge | F25: 42.5 | G25: =F25 -> 42.5 | H25: =G25 -> 42.5 | I25: =H25 -> 42.5 | J25: =I25 -> 42.5 | K25: =J25 -> 42.5 | L25: =K25 -> 42.5 | M25: =L25 -> 42.5 | N25: 100
C26: - the back edge of upper layer to pad edge
B28: Quality Check on site
C29: Pad Weight | D29: 5pc | F29: ○ | G29: ○ | H29: ○ | I29: ○ | J29: ○ | K29: ○ | L29: ○ | M29: ○ | N29: ○ | O29: ○ | P29: ○
C30: Pad Width | D30: 5pc | F30: ○ | G30: ○ | H30: ○ | I30: ○ | J30: ○ | K30: ○ | L30: ○ | M30: ○ | N30: ○ | O30: ○ | P30: ○
C31: The channel edge to left pad edge distance | D31: 5pc | F31: ○ | G31: ○ | M31: ○ | N31: ○ | O31: ○ | P31: ○
C32: Pad integrity | D32: 4pc | F32: ○ | G32: ○ | H32: ○ | I32: ○ | J32: ○ | K32: ○ | L32: ○
C33: Channel
C34: Channel Width | D34: 5pc | F34: ○ | G34: ○ | M34: ○ | N34: ○ | O34: ○ | P34: ○
C35: Whole channel width | D35: 5pc | F35: ○ | G35: ○ | M35: ○ | N35: ○ | O35: ○ | P35: ○
C36: Whole channel length | D36: 5pc | F36: ○ | G36: ○ | M36: ○ | N36: ○ | O36: ○ | P36: ○
B38: Quality Check in lab
C39: High priority test items
B40: 1 | C40: L-H pressure | D40: 4pc | F40: ○ | G40: ○ | H40: ○ | I40: ○ | J40: ○ | K40: ○ | L40: ○ | M40: ○ | N40: ○ | O40: ○ | P40: ○
B41: 2 | C41: National rewet | D41: 5pc | F41: ○ | G41: ○ | H41: ○ | I41: ○ | J41: ○ | K41: ○ | L41: ○ | M41: ○ | N41: ○ | O41: ○ | P41: ○
B42: 3 | C42: Cradle Intake & Distribute length | D42: 4pc | F42: ○ | G42: ○ | H42: ○ | I42: ○ | J42: ○ | K42: ○ | L42: ○ | M42: ○ | N42: ○ | O42: ○ | P42: ○
C43: The channel edge to front pad edge distance | D43: 5pc | F43: ○ | G43: ○ | H43: ○ | I43: ○ | J43: ○ | K43: ○ | L43: ○ | M43: ○ | N43: ○ | O43: ○ | P43: ○
...

Sheet Product Test
B1: CI-06 COCO V6 3rd round trial | G1: 测试均在中间加bonding
G2: 收样前需要确认：Pad重量，宽度，channel是否居中
C3: Code | G3: Code 1 | H3: Code 2 | I3: Control - 1 | J3: Control - 2 | K3: Code 3 | L3: Code 4 | M3: Code 5 | N3: Code 6 | O3: Code 7 | P3: Code 8 | Q3: Code 9 | R3: Code 10 | S3: Code 11 | T3: Code 12 | U3: Code 13 | V3: Code 14 | W3: Code 15 | X3: Code 16 | Y3: Code 17
C4: Code Design: | K4: Base On Control -2，搭配面层1 | L4: Base On Control -2，搭配面层2 | W4: #VALUE!
C5: LSS add on 7.75g
C6: PSS add on 7.75g
C7: Pad Length 382mm
C10: LSS | G10: Control-NR 511 | H10: Control-NR 511 | I10: Control-NR 511 | J10: Control-NR 511 | M10: Control-NR 511 | N10: Control-NR 511 | O10: Control-NR 511 | P10: Control-NR 511 | Q10: Code x | R10: 950 | S10: Control-NR 511 | T10: Control-NR 511 | U10: Control-NR 511 | V10: Control-NR 511 | W10: Control-NR 511 | X10: Control-NR 511 | Y10: Control-NR 511
C11: PSS | G11: Control-NR 511 | H11: Control-NR 511 | I11: Control-NR 511 | J11: Control-NR 511 | M11: 100% 610 | N11: 100% 950 | O11: 50% 610+ 50% 511 | P11: 50% 610+ 50% 950 | Q11: Control-NR 511 | R11: Control-NR 511 | S11: Control-NR 511 | T11: Control-NR 511 | U11: Control-NR 511 | V11: Control-NR 511 | W11: Control-NR 511 | X11: Control-NR 511 | Y11: Control-NR 511
C12: LSN | G12: Control-38g | H12: Control-38g | I12: Control-38g | J12: Control-38g | M12: Control-38g | N12: Control-38g | O12: Control-38g | P12: Control-38g | Q12: Control-38g | R12: Control-38g | S12: UNIKORN - 200mm | T12: Wangjin | U12: Control-38g | V12: Control-38g | W12: Control-38g | X12: Control-38g | Y12: Control-38g
C13: PSN | G13: Control-26g | H13: Control-26g | I13: Control-26g | J13: Control-26g | M13: Control-26g | N13: Control-26g | O13: Control-26g | P13: Control-26g | Q13: Control-26g | R13: Control-26g | S13: Control-26g | T13: Control-26g | U13: UNIKORN -155mm | V13: Control-26g | W13: Control-26g | X13: Control-26g | Y13: Control-26g
C14: REL | G14: Control-40g | H14: Control-40g | I14: Control-40g | J14: Control-40g | M14: Control-40g | N14: Control-40g | O14: Control-40g | P14: Control-40g | Q14: Control-40g | R14: Control-40g | S14: Control-40g | T14: Control-40g | U14: Control-40g | V14: Minrui | W14: Control-40g | X14: Control-40g | Y14: Control-40g
C15: Adh. | G15: 亲水胶 3.5*4 | H15: 亲水胶 2*4 | I15: Control -2*4 | J15: Control -3.5*4 | M15: Control -3.5*4 | N15: Control -3.5*4 | O15: Control -3.5*4 | P15: Control -3.5*4 | Q15: Control -3.5*4 | R15: Control -3.5*4 | S15: Control -3.5*4 | T15: Control -3.5*4 | U15: Control -3.5*4 | V15: Control -3.5*4 | W15: Control -3.5*4 | X15: Control -3.5*4 | Y15: Control -3.5*4
C16: Liner - 手工样 | G16: Control-50g | H16: Control-50g | I16: Control-50g | J16: Control-50g | K16: Yanjan Code 1: 50gsm | L16: Chuanyue Code 2 | M16: Control-50g | N16: Control-50g | O16: Control-50g | P16: Control-50g | Q16: Control-50g | R16: Control-50g | S16: Control-50g | T16: Control-50g | U16: Control-50g | V16: Control-50g | W16: Control-50g | X16: Control-50g | Y16: Control-50g
C17: Tar. Weight | G17: ='Target Weight'!H21 -> 22.81721 | H17: ='Target Weight'!I21 -> 22.50206 | I17: =H17 -> 22.50206 | J17: =G17 -> 22.81721 | M17: =J17 -> 22.81721 | N17: =M17 -> 22.81721 | O17: =N17 -> 22.81721 | P17: =O17 -> 22.81721 | Q17: =P17 -> 22.81721 | R17: =Q17 -> 22.81721 | S17: ='Target Weight'!J21 -> 21.44201 | T17: =J17 -> 22.81721 | U17: ='Target Weight'!K21 -> 22.46195 | V17: ='Target Weight'!L21 -> 22.17545 | W17: ='Target Weight'!H31 -> 22.12006 | X17: =W17 -> 22.12006 | Y17: =J17 -> 22.81721
C18: USL + 0.5 | G18: =G17+0.5 -> 23.31721 | H18: =H17+0.5 -> 23.00206 | I18: =I17+0.5 -> 23.00206 | J18: =J17+0.5 -> 23.31721 | M18: =J18 -> 23.31721 | N18: =M18 -> 23.31721 | O18: =N18 -> 23.31721 | P18: =O18 -> 23.31721 | Q18: =P18 -> 23.31721 | R18: =Q18 -> 23.31721 | S18: ='Target Weight'!J23 -> 22.514111 | T18: =J18 -> 23.31721 | U18: ='Target Weight'!K23 -> 23.585048 | V18: ='Target Weight'!L23 -> 23.284222 | W18: ='Target Weight'!H33 -> 23.226063 | X18: =W18 -> 23.226063 | Y18: =J18 -> 23.31721
C19: LSL - 0.5 | G19: =G17-0.5 -> 22.31721 | H19: =H17-0.5 -> 22.00206 | I19: =I17-0.5 -> 22.00206 | J19: =J17-0.5 -> 22.31721 | M19: =J19 -> 22.31721 | N19: =M19 -> 22.31721 | O19: =N19 -> 22.31721 | P19: =O19 -> 22.31721 | Q19: =P19 -> 22.31721 | R19: =Q19 -> 22.31721 | S19: ='Target Weight'!J22 -> 20.369909 | T19: =J19 -> 22.31721 | U19: ='Target Weight'!K22 -> 21.338853 | V19: ='Target Weight'!L22 -> 21.066677 | W19: ='Target Weight'!H32 -> 21.014057 | X19: =W19 -> 21.014057 | Y19: =J19 -> 22.31721
C20: ADH width | G20: 137.5 | H20: 137.5 | I20: 137.5 | J20: 137.5 | K20: 137.5 | L20: 137.5 | M20: 137.5 | N20: 137.5 | O20: 137.5 | P20: 137.5 | Q20: 137.5 | R20: 137.5 | S20: 137.5 | T20: 137.5 | U20: 137.5 | V20: 137.5 | W20: 125 | X20: 125 | Y20: 137.5
C21: Remark | G21: Control面层预计周二抵达 | L21: 等待传越打样 | W21: -16,17 在一个成型鼓 -PSN, REL需要换成适合110mm Pad -胶宽需要减窄 -需要两卷
B23: Quality Check in lab
C24: Pad integrity | D24: 取样前 | G24: ○ | H24: ○ | I24: ○ | J24: ○
B25: ⭐⭐⭐ | C25: Pad Weight | D25: Every pc | G25: ○ | H25: ○ | I25: ○ | J25: ○ | K25: ○ | L25: ○ | M25: ○ | N25: ○ | O25: ○ | P25: ○ | Q25: ○ | R25: ○ | S25: ○ | T25: ○ | U25: ○ | V25: ○ | W25: ○ | X25: ○ | Y25: ○
B26: ⭐⭐⭐ | C26: National rewet | D26: 5pc | G26: ○ | H26: ○ | I26: ○ | J26: ○ | K26: ○ | L26: ○ | M26: ○ | N26: ○ | O26: ○ | P26: ○ | Q26: ○ | R26: ○ | S26: ○ | T26: ○ | U26: ○ | V26: ○ | W26: ○ | X26: ○ | Y26: ○
B27: ⭐⭐⭐ | C27: Cradle Intake & Distribute length | D27: 4pc | G27: ○ | H27: ○ | I27: ○ | J27: ○ | K27: ○ | L27: ○ | M27: ○ | N27: ○ | O27: ○ | P27: ○ | Q27: ○ | R27: ○ | S27: ○ | T27: ○ | U27: ○ | V27: ○ | W27: ○ | X27: ○ | Y27: ○
C28: L-H pressure | D28: 4pc | G28: ○ | H28: ○ | I28: ○ | J28: ○ | K28: ○ | L28: ○ | M28: ○ | N28: ○ | O28: ○ | P28: ○ | Q28: ○ | R28: ○ | S28: ○ | T28: ○ | U28: ○ | V28: ○ | W28: ○ | X28: ○ | Y28: ○
C29: Mannequins - Side（测量扩散并拍照） | D29: 6pc | G29: TBD | H29: TBD | I29: TBD | J29: ○ | K29: TBD | L29: TBD | M29: TBD | N29: TBD | O29: TBD | P29: TBD | Q29: TBD | R29: TBD | S29: TBD | T29: TBD | U29: TBD | V29: TBD | W29: ○ | X29: ○ | Y29: ○
C30: Mannequins - Prone（测量扩散并拍照） | D30: 6pc | G30: TBD | H30: TBD | I30: TBD | J30: ○ | K30: TBD | L30: TBD | M30: TBD | N30: TBD | O30: TBD | P30: TBD | Q30: TBD | R30: TBD | S30: TBD | T30: TBD | U30: TBD | V30: TBD | W30: ○ | X30: ○ | Y30: ○
C31: Mannequins - Supine（测量扩散并拍照） | D31: 6pc | G31: TBD | H31: TBD | I31: TBD | J31: ○ | K31: TBD | L31: TBD | M31: TBD | N31: TBD | O31: TBD | P31: TBD | Q31: TBD | R31: TBD | S31: TBD | T31: TBD | U31: TBD | V31: TBD | W31: ○ | X31: ○ | Y31: ○
C32: surface moisture | D32: 5pc | G32: ○ | H32: ○ | I32: ○ | J32: ○
C33: Run off (MD) | D33: 5pc | G33: ○ | H33: ○ | I33: ○ | J33: ○
C34: FIFE intake | D34: 4pc | G34: ○ | H34: ○ | I34: ○ | J34: ○ | K34: ○ | L34: ○ | M34: ○ | N34: ○ | O34: ○ | P34: ○ | Q34: ○ | R34: ○ | S34: ○ | T34: ○ | U34: ○ | V34: ○ | W34: ○ | X34: ○ | Y34: ○
C35: SAM Density | D35: 5pc | J35: ○ | W35: ○ | Y35: ○
C36: 备注
AC106: 测试下30min 芯吸高度 & 瞬时的芯吸高度 Minrui 翻面：毛面朝向 复测N610 原材料测试

Sheet Daily Plan
B2: Date | C2: 芯体机 | D2: 手工样 & 测试
B3: Sep.21 | C3: -完成芯体机开机准备 -完成换胶工作 -完成两个胶量的标定工作 -完成code 1,2 收样 | D3: - 完成原材料测试
B4: 22 | C4: -将胶更换为control -完成两个胶量的标定工作 -完成control 1, Control 2 收样 -完成code 5收样 | D4: -手工样准备：面层+支持层 -完成code 1,2 手工样制作 -完成code 1,2回渗，cradle，L-H测试
B5: 23 | C5: -完成code 6,7收样 | D5: -完成Control 1, Control 2以及code 5的手工样制作 -完成Control 1, Control 2以及code 5回渗，cradle，L-H测试 -完成Control 1的SAM Density
B6: 24 | C6: -完成code 8,9收样 | D6: -完成Code 6,7 的手工样制作 -完成code 6,7 回渗，cradle，L-H测试 -完成code 1,2，Control 1, Control 2的surface moisture和run off | E6: 40
B7: 28 | C7: -完成code 10,11,12,13,14收样 | D7: -完成Code 8，9 的手工样制作 -完成code 8，9 回渗，cradle，L-H测试 -完成code 1,2，Control 1, Control 2的surface moisture和run off | E7: 120
B8: 29 | C8: -完成code 15,16收样 | D8: -完成Code 10，11，12，13，14 的手工样制作
B9: 30 | C9: ‘-完成code 17收样 -设备现场恢复 | D9: -完成Code 10，11，12，13，14 的手工样制作回渗，cradle，L-H测试 -完成code 15,16手工样制作

Sheet Material Test 
A1: Liner-1 Yanjan Code 1: 50gsm | B1: Basis Weight(gsm) 基重 | C1: Thickness(Spooling Roll Outside at 0.2kpa) 厚度 | D1: MD Strength (N/2inch) | E1: CD Strength (N/2inch) | F1: MD Elongation (%) | G1: CD Elongation (%) | H1: Strike-Through (sec.) 亲水性 | I1: Wetback(g) 返渗 | J1: Between layer delamination Strength(N) 3D面层层压强度 | K1: PH | L1: Run off (g) | M1: Lints (Abrasion)起毛
A2: 1 | B2: 45.21 | C2: 1.648 | D2: 6128.77 | E2: 743.12 | F2: 48.41 | G2: 86.42 | H2: 0.8 | I2: 0.039 | J2: 83.43 | K2: 7.16 | L2: 0 | M2: 见右图
A3: 2 | B3: 44.56 | C3: 2.055 | D3: 6063.51 | E3: 795.8 | F3: 46.8 | G3: 91.47 | H3: 0.87 | I3: 0.039 | J3: 96.84 | K3: 7.07 | L3: 0 | M3: 每个分区三组
A4: 3 | B4: 46.01 | C4: 1.761 | D4: 5385.67 | E4: 727.99 | F4: 40.97 | G4: 86.07 | H4: 0.74 | I4: 0.037 | J4: 115.37 | K4: 7.1 | L4: 0
A5: 4 | B5: 46.21 | C5: 1.476 | D5: 6064.9 | E5: 786.75 | F5: 48.77 | G5: 73.29 | H5: 0.9 | I5: 0.039 | J5: 139.32 | K5: 7.11 | L5: 0
A6: 5 | B6: 44.12 | C6: 1.665 | D6: 5972.32 | E6: 715.84 | F6: 46.69 | G6: 62.65 | H6: 1.06 | I6: 0.037 | J6: 141.42 | K6: 7.12 | L6: 0
A7: Ave | B7: =AVERAGE(B2:B6) -> 45.222 | C7: =AVERAGE(C2:C6) -> 1.721 | D7: =AVERAGE(D2:D6) -> 5923.034 | E7: =AVERAGE(E2:E6) -> 753.9 | F7: =AVERAGE(F2:F6) -> 46.328 | G7: =AVERAGE(G2:G6) -> 79.98 | H7: =AVERAGE(H2:H6) -> 0.874 | I7: =AVERAGE(I2:I6) -> 0.0382 | ... M7: =AVERAGE(M2:M6) -> #DIV/0!
A8: Liner-2 Code 2-A: 30 gsm chuanyue | B8: Basis Weight(gsm) | C8: Thickness(Spooling Roll Outside at 0.2kpa) | D8: MD Strength (N/2inch) | E8: CD Strength (N/2inch) | F8: MD Elongation (%) | G8: CD Elongation (%) | H8: Strike-Through (sec.) | I8: Wetback(g) | J8: Between layer delamination Strength(N) | K8: PH | L8: Run off (g) | M8: Lints (Abrasion)
A9: 1
A10: 2 | C10: 未到货，暂不测试
A11: 3
A12: 4
A13: 5
A14: Ave | B14: =AVERAGE(B9:B13) -> #DIV/0! | C14: =AVERAGE(C9:C13) -> #DIV/0! | D14: =AVERAGE(D9:D13) -> #DIV/0! | E14: =AVERAGE(E9:E13) -> #DIV/0! | F14: =AVERAGE(F9:F13) -> #DIV/0! | G14: =AVERAGE(G9:G13) -> #DIV/0! | H14: =AVERAGE(H9:H13) -> #DIV/0! | I14: =AVERAGE(I9:I13) -> #DIV/0! | ... M14: =AVERAGE(M9:M13) -> #DIV/0!
A16: REL Minrui | B16: Basis Weight (gsm) | C16: Thickness(mm)(Roll Outside at 0.2kpa) | D16: Tensile Strength MD | E16: Tensile Strength CD | F16: MD Elongation at biggest strength (%) | G16: CD Elongation at biggest strength (%) | H16: Liquid Strike-Through(sec.) | I16: Wetback (g) | J16: PH Value
A17: 1 | B17: 33.74 | C17: 0.851 | D17: 2289.26 | E17: 568.74 | F17: 56.85 | G17: 81.34 | H17: 1.25 | I17: 0.049 | J17: 6.79
A18: 2 | B18: 33.62 | C18: 0.889 | D18: 2364.22 | E18: 584.45 | F18: 50.45 | G18: 84.09 | H18: 1.35 | I18: 0.053 | J18: 6.86
A19: 3 | B19: 33.52 | C19: 0.851 | D19: 2328.32 | E19: 523.3 | F19: 50.79 | G19: 66.67 | H19: 1.24 | I19: 0.044 | J19: 6.62
A20: 4 | B20: 34.08 | C20: 0.899 | D20: 2411.03 | E20: 575.01 | F20: 55.93 | G20: 85.72 | H20: 1.29 | I20: 0.039 | J20: 6.65
A21: 5 | B21: 32.44 | C21: 0.835 | D21: 2348.97 | E21: 603.07 | F21: 52.76 | G21: 79.28 | H21: 1.03 | I21: 0.052 | J21: 6.53
A22: Ave | B22: =AVERAGE(B17:B21) -> 33.48 | C22: =AVERAGE(C17:C21) -> 0.865 | D22: =AVERAGE(D17:D21) -> 2348.36 | E22: =AVERAGE(E17:E21) -> 570.914 | F22: =AVERAGE(F17:F21) -> 53.356 | G22: =AVERAGE(G17:G21) -> 79.42 | H22: =AVERAGE(H17:H21) -> 1.232 | I22: =AVERAGE(I17:I21) -> 0.0474 | J22: =AVERAGE(J17:J21) -> 6.69
A24: LSN-1 含三叶草粘胶纤维王金 | B24: 基重(gsm) | C24: 材料厚度[2] (卷外@0.20Kpa(2mm)) | D24: MD拉伸强度 | E24: CD拉伸强度 | F24: MD延伸率% | G24: CD延伸率% | H24: 含水率% | I24: 液体穿透时间 | J24: 返渗 | K24: 芯体吸收高度（爬坡 反重力测试） | L24: 爬坡时长5min
A25: 1 | B25: 39.18 | C25: 0.364 | D25: 3650.31 | E25: 1116.34 | F25: 21.24 | G25: 107.94 | H25: 0.107 | I25: 1.59 | J25: 0.913 | K25: 139.5
A26: 2 | B26: 38.46 | C26: 0.374 | D26: 2380.33 | E26: 621.39 | F26: 23.9 | G26: 108.77 | H26: 0.0786 | I26: 1.58 | J26: 0.907 | K26: 139.5
A27: 3 | B27: 38.08 | C27: 0.38 | D27: 3258.88 | E27: 765.71 | F27: 25.48 | G27: 103.36 | H27: 0.1026 | I27: 1.55 | J27: 0.898 | K27: 125
A28: 4 | B28: 38.7 | C28: 0.371 | D28: 2482.23 | E28: 797.81 | F28: 27.52 | G28: 109.37 | H28: 0.0992 | I28: 1.65 | J28: 0.92 | K28: 140
A29: 5 | B29: 39.36 | C29: 0.361 | D29: 4096.92 | E29: 1033.28 | F29: 20.58 | G29: 105.37 | H29: 0.1135 | I29: 1.6 | J29: 0.842 | K29: 142
A30: Ave | B30: =AVERAGE(B25:B29) -> 38.756 | C30: =AVERAGE(C25:C29) -> 0.37 | D30: =AVERAGE(D25:D29) -> 3173.734 | E30: =AVERAGE(E25:E29) -> 866.906 | F30: =AVERAGE(F25:F29) -> 23.744 | G30: =AVERAGE(G25:G29) -> 106.962 | H30: =AVERAGE(H25:H29) -> 0.10018 | I30: =AVERAGE(I25:I29) -> 1.594 | ... K30: =AVERAGE(K25:K29) -> 137.2
A31: LSN-2 Unikorn幅宽200mm | B31: 基重(gsm) | C31: 材料厚度[2] (卷外@0.20Kpa(2mm)) | D31: MD拉伸强度 | E31: CD拉伸强度 | F31: MD延伸率% | G31: CD延伸率% | H31: 含水率% | I31: 液体穿透时间 | J31: 返渗 | K31: 芯体吸收高度（爬坡 反重力测试）
A32: 1 | B32: 20.12 | C32: 0.2674 | D32: 884.14 | E32: 390.8 | F32: 36.43 | G32: 91.77 | H32: 0.0285 | I32: 2.83 | J32: 0.145 | K32: 45
A33: 2 | B33: 20.2 | C33: 0.2744 | D33: 709.71 | E33: 410.68 | F33: 47.17 | G33: 64.79 | H33: 0.0154 | I33: 2.46 | J33: 0.097 | K33: 57.5 | L33: 两款材料相同，仅幅宽不同，测试一种
A34: 3 | B34: 21.02 | C34: 0.2752 | D34: 671.01 | E34: 502.35 | F34: 28.68 | G34: 82.07 | H34: 0.0251 | I34: 2.93 | J34: 0.122 | K34: 53.5
A35: 4 | B35: 20.06 | C35: 0.2687 | D35: 723.49 | E35: 546.72 | F35: 26.88 | G35: 81.2 | H35: 0.0234 | I35: 2.84 | J35: 0.125 | K35: 47.5
A36: 5 | B36: 20.86 | C36: 0.2621 | D36: 742.7 | E36: 458.49 | F36: 30.18 | G36: 58.3 | H36: 0.0283 | I36: 3.09 | J36: 0.118 | K36: 52
A37: Ave | B37: =AVERAGE(B32:B36) -> 20.452 | C37: =AVERAGE(C32:C36) -> 0.26956 | D37: =AVERAGE(D32:D36) -> 746.21 | E37: =AVERAGE(E32:E36) -> 461.808 | F37: =AVERAGE(F32:F36) -> 33.868 | G37: =AVERAGE(G32:G36) -> 75.626 | H37: =AVERAGE(H32:H36) -> 0.02414 | I37: =AVERAGE(I32:I36) -> 2.83 | ... K37: =AVERAGE(K32:K36) -> 51.1
A39: PSN Unikorn幅宽150mm | B39: 基重(gsm) | C39: 材料厚度[2] (卷外@0.20Kpa(2mm)) | D39: MD拉伸强度 | E39: CD拉伸强度 | F39: MD延伸率% | G39: CD延伸率% | H39: 含水率% | I39: 液体穿透时间 | J39: 返渗 | K39: 芯体吸收高度（爬坡 反重力测试）
A40: 1 | H40: 0.0287 | K40: 33.25
A41: 2 | H41: 0.0283 | K41: 37.5
A42: 3 | H42: 0.0262 | K42: 35.5
A43: 4 | H43: 0.0241 | K43: 40
...

Sheet LSN&PSN
B2: LSN-1 含三叶草粘胶纤维王金 | C2: 基重(gsm) | D2: 材料厚度[2] (卷外@0.20Kpa(2mm)) | E2: MD拉伸强度 | F2: CD拉伸强度 | G2: MD延伸率% | H2: CD延伸率% | I2: 含水率% | J2: 液体穿透时间 | K2: 返渗 | L2: 芯体吸收高度（爬坡 反重力测试）
B3: 1 | C3: 39.18 | D3: 0.364 | E3: 3650.31 | F3: 1116.34 | G3: 21.24 | H3: 107.94 | I3: 0.107 | J3: 1.59 | K3: 0.913 | L3: 139.5
B4: 2 | C4: 38.46 | D4: 0.374 | E4: 2380.33 | F4: 621.39 | G4: 23.9 | H4: 108.77 | I4: 0.0786 | J4: 1.58 | K4: 0.907 | L4: 139.5
B5: 3 | C5: 38.08 | D5: 0.38 | E5: 3258.88 | F5: 765.71 | G5: 25.48 | H5: 103.36 | I5: 0.1026 | J5: 1.55 | K5: 0.898 | L5: 125
B6: 4 | C6: 38.7 | D6: 0.371 | E6: 2482.23 | F6: 797.81 | G6: 27.52 | H6: 109.37 | I6: 0.0992 | J6: 1.65 | K6: 0.92 | L6: 140
B7: 5 | C7: 39.36 | D7: 0.361 | E7: 4096.92 | F7: 1033.28 | G7: 20.58 | H7: 105.37 | I7: 0.1135 | J7: 1.6 | K7: 0.842 | L7: 142
B8: Ave | C8: =AVERAGE(C3:C7) -> 38.756 | D8: =AVERAGE(D3:D7) -> 0.37 | E8: =AVERAGE(E3:E7) -> 3173.734 | F8: =AVERAGE(F3:F7) -> 866.906 | G8: =AVERAGE(G3:G7) -> 23.744 | H8: =AVERAGE(H3:H7) -> 106.962 | I8: =AVERAGE(I3:I7) -> 0.10018 | J8: =AVERAGE(J3:J7) -> 1.594 | ... L8: =AVERAGE(L3:L7) -> 137.2
B9: LSN-2 Unikorn幅宽200mm | C9: 基重(gsm) | D9: 材料厚度[2] (卷外@0.20Kpa(2mm)) | E9: MD拉伸强度 | F9: CD拉伸强度 | G9: MD延伸率% | H9: CD延伸率% | I9: 含水率% | J9: 液体穿透时间 | K9: 返渗 | L9: 芯体吸收高度（爬坡 反重力测试）
B10: 1 | C10: 20.12 | D10: 0.2674 | E10: 884.14 | F10: 390.8 | G10: 36.43 | H10: 91.77 | I10: 0.0285 | J10: 2.83 | K10: 0.145 | L10: 45
B11: 2 | C11: 20.2 | D11: 0.2744 | E11: 709.71 | F11: 410.68 | G11: 47.17 | H11: 64.79 | I11: 0.0154 | J11: 2.46 | K11: 0.097 | L11: 57.5
B12: 3 | C12: 21.02 | D12: 0.2752 | E12: 671.01 | F12: 502.35 | G12: 28.68 | H12: 82.07 | I12: 0.0251 | J12: 2.93 | K12: 0.122 | L12: 53.5 | N12: LSN-三叶草 | O12: Unikorn | P12: Control LSN | Q12: Control PSN
B13: 4 | C13: 20.06 | D13: 0.2687 | E13: 723.49 | F13: 546.72 | G13: 26.88 | H13: 81.2 | I13: 0.0234 | J13: 2.84 | K13: 0.125 | L13: 47.5
B14: 5 | C14: 20.86 | D14: 0.2621 | E14: 742.7 | F14: 458.49 | G14: 30.18 | H14: 58.3 | I14: 0.0283 | J14: 3.09 | K14: 0.118 | L14: 52
B15: Ave | C15: =AVERAGE(C10:C14) -> 20.452 | D15: =AVERAGE(D10:D14) -> 0.26956 | E15: =AVERAGE(E10:E14) -> 746.21 | F15: =AVERAGE(F10:F14) -> 461.808 | G15: =AVERAGE(G10:G14) -> 33.868 | H15: =AVERAGE(H10:H14) -> 75.626 | I15: =AVERAGE(I10:I14) -> 0.02414 | J15: =AVERAGE(J10:J14) -> 2.83 | ... L15: =AVERAGE(L10:L14) -> 51.1
B16: Control LSN
L17: 111.5
L18: 110
L19: 107.5
L20: 111.5
L21: 107
J22: 2 | L22: =AVERAGE(L17:L21) -> 109.5
B23: Control PSN | C23: 基重(gsm) | D23: 材料厚度[2] (卷外@0.20Kpa(2mm)) | E23: MD拉伸强度 | F23: CD拉伸强度 | G23: MD延伸率% | H23: CD延伸率% | I23: 含水率% | J23: 液体穿透时间 | K23: 返渗 | L23: 芯体吸收高度（爬坡 反重力测试）
L24: 14
L25: 17
L26: 17.5
L27: 14
L28: 17
B29: Ave | C29: 26 | D29: 0.42 | J29: 1.5 | L29: =AVERAGE(L24:L28) -> 15.9

Sheet 芯吸高度
A1: LSN | B1: 10s | K1: 30min
B2: 58.5 | K2: 119.5
B3: 61.5 | K3: 125.5
B4: 63 | K4: 123.5
B5: 62 | K5: 128
B6: 63 | K6: 130.5
B7: ave | C7: =AVERAGE(B2:B6) -> 61.6 | K7: ave | L7: =AVERAGE(K2:K6) -> 125.4
B8: std | C8: =STDEV(B2:B6) -> 1.8506756 | K8: std | L8: =STDEV(K2:K6) -> 4.2190046
A13: PSN | B13: 12 | K13: 22.5
B14: 14 | K14: 15.5
B15: 12.5 | K15: 17.5
B16: 11 | K16: 15.5
B17: 11.5 | K17: 17.5
B18: ave | C18: =AVERAGE(B13:B17) -> 12.2 | K18: ave | L18: =AVERAGE(K13:K17) -> 17.7
B19: std | C19: =STDEV(B13:B17) -> 1.1510864 | K19: std | L19: =STDEV(K13:K17) -> 2.8635642
A25: unikorn | B25: 15 | K25: 71
B26: 8 | K26: 60
B27: 5.5 | K27: 66
B28: 8 | K28: 64.5
B29: 12 | K29: 62
B30: ave | C30: =AVERAGE(B25:B29) -> 9.7 | K30: ave | L30: =AVERAGE(K25:K29) -> 64.7
B31: std | C31: =STDEV(B25:B29) -> 3.7682887 | K31: std | L31: =STDEV(K25:K29) -> 4.2071368
A37: 王金 | B37: 59.5 | K37: 157
B38: 59 | K38: 168
B39: 71.5 | K39: 166.5
B40: 75.5 | K40: 181
B41: 78 | K41: 170.5
B42: ave | C42: =AVERAGE(B37:B41) -> 68.7 | K42: ave | L42: =AVERAGE(K37:K41) -> 168.6
B43: std | C43: =STDEV(B37:B41) -> 8.9344838 | K43: std | L43: =STDEV(K37:K41) -> 8.6124909
E49: 10s | F49: 5min | G49: 30min
D50: Control LSN | E50: =C7 -> 61.6 | F50: ='LSN&PSN'!L22 -> 109.5 | G50: =L7 -> 125.4
D51: Control PSN | E51: =C18 -> 12.2 | F51: ='LSN&PSN'!$L$29 -> 15.9 | G51: =L18 -> 17.7
D52: Unikorn | E52: =C30 -> 9.7 | F52: ='LSN&PSN'!$L$15 -> 51.1 | G52: =L30 -> 64.7
D53: Wangjin 三叶草 | E53: =C42 -> 68.7 | F53: ='LSN&PSN'!$L$8 -> 137.2 | G53: =L42 -> 168.6

Sheet Check before collecting
A1: Control | B1: Pad Weight | C1: Pad Width | D1: The channel edge to left pad edge distance | E1: Pad integrity | F1: Channel | G1: Channel Width | H1: Whole channel width | I1: Whole channel length
A2: 1
A3: 2
A4: 3
A5: 4
A6: 5
A7: adv | B7: =AVERAGE(B2:B6) -> #DIV/0! | C7: =AVERAGE(C2:C6) -> #DIV/0! | D7: =AVERAGE(D2:D6) -> #DIV/0! | E7: =AVERAGE(E2:E6) -> #DIV/0! | F7: =AVERAGE(F2:F6) -> #DIV/0! | G7: =AVERAGE(G2:G6) -> #DIV/0! | H7: =AVERAGE(H2:H6) -> #DIV/0! | I7: =AVERAGE(I2:I6) -> #DIV/0!
A8: Std | B8: =STDEV(B2:B6) -> #DIV/0! | C8: =STDEV(C2:C6) -> #DIV/0! | D8: =STDEV(D2:D6) -> #DIV/0! | E8: =STDEV(E2:E6) -> #DIV/0! | F8: =STDEV(F2:F6) -> #DIV/0! | G8: =STDEV(G2:G6) -> #DIV/0! | H8: =STDEV(H2:H6) -> #DIV/0! | I8: =STDEV(I2:I6) -> #DIV/0!
A10: Code 1 | B10: Pad Weight | C10: Pad Width | D10: The channel edge to left pad edge distance | E10: Pad integrity | F10: Channel | G10: Channel Width | H10: Whole channel width | I10: Whole channel length
A11: 1
A12: 2
A13: 3
A14: 4
A15: 5
A16: adv | D16: =AVERAGE(D11:D15) -> #DIV/0! | E16: =AVERAGE(E11:E15) -> #DIV/0! | F16: =AVERAGE(F11:F15) -> #DIV/0! | G16: =AVERAGE(G11:G15) -> #DIV/0! | H16: =AVERAGE(H11:H15) -> #DIV/0! | I16: =AVERAGE(I11:I15) -> #DIV/0!
A17: Std | D17: =STDEV(D11:D15) -> #DIV/0! | E17: =STDEV(E11:E15) -> #DIV/0! | F17: =STDEV(F11:F15) -> #DIV/0! | G17: =STDEV(G11:G15) -> #DIV/0! | H17: =STDEV(H11:H15) -> #DIV/0! | I17: =STDEV(I11:I15) -> #DIV/0!
A19: Code 2 | B19: Pad Weight | C19: Pad Width | D19: The channel edge to left pad edge distance | E19: Pad integrity | F19: Channel | G19: Channel Width | H19: Whole channel width | I19: Whole channel length
A20: 1
A21: 2
A22: 3
A23: 4
A24: 5
A25: adv | D25: =AVERAGE(D20:D24) -> #DIV/0! | E25: =AVERAGE(E20:E24) -> #DIV/0! | F25: =AVERAGE(F20:F24) -> #DIV/0! | G25: =AVERAGE(G20:G24) -> #DIV/0! | H25: =AVERAGE(H20:H24) -> #DIV/0! | I25: =AVERAGE(I20:I24) -> #DIV/0!
A26: Std | D26: =STDEV(D20:D24) -> #DIV/0! | E26: =STDEV(E20:E24) -> #DIV/0! | F26: =STDEV(F20:F24) -> #DIV/0! | G26: =STDEV(G20:G24) -> #DIV/0! | H26: =STDEV(H20:H24) -> #DIV/0! | I26: =STDEV(I20:I24) -> #DIV/0!
A28: Code 3 | B28: Pad Weight | C28: Pad Width | D28: The channel edge to left pad edge distance | E28: Pad integrity | F28: Channel | G28: Channel Width | H28: Whole channel width | I28: Whole channel length
A29: 1
A30: 2
A31: 3
A32: 4
A33: 5
A34: adv | D34: =AVERAGE(D29:D33) -> #DIV/0! | E34: =AVERAGE(E29:E33) -> #DIV/0! | F34: =AVERAGE(F29:F33) -> #DIV/0! | G34: =AVERAGE(G29:G33) -> #DIV/0! | H34: =AVERAGE(H29:H33) -> #DIV/0! | I34: =AVERAGE(I29:I33) -> #DIV/0!
A35: Std | D35: =STDEV(D29:D33) -> #DIV/0! | E35: =STDEV(E29:E33) -> #DIV/0! | F35: =STDEV(F29:F33) -> #DIV/0! | G35: =STDEV(G29:G33) -> #DIV/0! | H35: =STDEV(H29:H33) -> #DIV/0! | I35: =STDEV(I29:I33) -> #DIV/0!
A37: Code 4 | B37: Pad Weight | C37: Pad Width | D37: The channel edge to left pad edge distance | E37: Pad integrity | F37: Channel | G37: Channel Width | H37: Whole channel width | I37: Whole channel length
A38: 1
A39: 2
A40: 3
A41: 4
A42: 5
A43: adv | D43: =AVERAGE(D38:D42) -> #DIV/0! | E43: =AVERAGE(E38:E42) -> #DIV/0! | F43: =AVERAGE(F38:F42) -> #DIV/0! | G43: =AVERAGE(G38:G42) -> #DIV/0! | H43: =AVERAGE(H38:H42) -> #DIV/0! | I43: =AVERAGE(I38:I42) -> #DIV/0!
A44: Std | D44: =STDEV(D38:D42) -> #DIV/0! | E44: =STDEV(E38:E42) -> #DIV/0! | F44: =STDEV(F38:F42) -> #DIV/0! | G44: =STDEV(G38:G42) -> #DIV/0! | H44: =STDEV(H38:H42) -> #DIV/0! | I44: =STDEV(I38:I42) -> #DIV/0!
...

Sheet Lab data form
A1: Code 1 | B1: 国标重量 | C1: 厚度 | D1: 国标第一次吸收时间 | E1: 国标第二次吸收时间 | F1: 国标回渗 | G1: 国标渗漏 | H1: Cradle 重量 | I1: Cradle 1st intake | J1: Cradle 2nd intake | K1: Cradle 3rd intake | L1: Cradle扩散长度 | M1: L-H Weight | N1: L intake time | O1: L Rewet | P1: L Residue | Q1: H intake time | R1: H Rewet | S1: H Residue | T1: L-H 扩散长度 | U1: Weight after intake | V1: Surface Moisture重量 | W1: Surface Moisture吸收时间 | X1: Surface Moisture回渗 | Y1: Run off | Z1: FTFE 1st intake time | AA1: FIFE leakage | AB1: FTFE 2st intake time | AC1: FIFE leakage | AD1: FTFE Rewet | AE1: FTFE 3st intake time | AF1: FIFE leakage | AG1: Pad Integrity
A2: 1 | B2: 36.37 | D2: 25.77 | E2: 26.6 | F2: 0.51 | G2: 0.51 | H2: 36.44 | I2: 13.82 | J2: 10.97 | K2: 28.19 | L2: 208 | M2: 36.39 | N2: 8.72 | O2: 0.13 | P2: 0.11 | Q2: 15.28 | R2: 0.25 | S2: 0.06 | T2: 335 | U2: 202.89 | V2: 36.8 | W2: 15.25 | X2: 0.16 | Y2: 0 | Z2: 22.59 | AA2: 0 | AB2: 16.59 | AC2: 0 | AD2: 9.12 | AE2: 11.43 | AF2: 0 | AG2: 300
A3: 2 | B3: 36.26 | D3: 25.2 | E3: 26.6 | F3: 0.25 | G3: 0.54 | H3: 36.41 | I3: 13.85 | J3: 9.82 | K3: 26.22 | L3: 206 | M3: 36.39 | N3: 7.57 | O3: 0.17 | P3: 0.06 | Q3: 13.57 | R3: 0.27 | S3: 0.04 | T3: 320.5 | U3: 202.77 | V3: 36.75 | W3: 18.09 | X3: 0.19 | Y3: 0 | Z3: 18.19 | AA3: 0 | AB3: 9.58 | AC3: 0 | AD3: 4.65 | AE3: 7.39 | AF3: 0 | AG3: 300
A4: 3 | B4: 36.38 | D4: 24.86 | E4: 25.17 | F4: 0.38 | G4: 0.56 | H4: 36.48 | I4: 13.53 | J4: 10.84 | K4: 30.44 | L4: 199 | M4: 36.53 | N4: 9.09 | O4: 0.1 | P4: 0.03 | Q4: 13.16 | R4: 0.29 | S4: 0.04 | T4: 317.5 | U4: 202.5 | V4: 36.71 | W4: 18.16 | X4: 0.16 | Y4: 0 | Z4: 16.53 | AA4: 0 | AB4: 8.18 | AC4: 0 | AD4: 7.36 | AE4: 6.14 | AF4: 0 | AG4: 300
A5: 4 | B5: 36.13 | D5: 24.83 | E5: 26.04 | F5: 0.32 | G5: 0.55 | H5: 36.28 | I5: 13.25 | J5: 9.72 | K5: 32.88 | L5: 201 | M5: 36.34 | N5: 6.31 | O5: 0.15 | P5: 0.08 | Q5: 15.31 | R5: 0.27 | S5: 0.06 | T5: 315.5 | U5: 202.2 | V5: 36.65 | W5: 16.43 | X5: 0.16 | Y5: 0 | Z5: 14.62 | AA5: 0 | AB5: 7.24 | AC5: 0 | AD5: 8.47 | AE5: 7.24 | AF5: 0 | AG5: 300
A6: 5 | B6: 36.37 | D6: 24.64 | E6: 26.78 | F6: 0.15 | G6: 0.54 | V6: 36.57 | W6: 16.5 | X6: 0.19 | Y6: 0 | AG6: 300
A7: adv | B7: =AVERAGE(B2:B6) -> 36.302 | C7: =AVERAGE(C2:C6) -> #DIV/0! | D7: =AVERAGE(D2:D6) -> 25.06 | E7: =AVERAGE(E2:E6) -> 26.238 | F7: =AVERAGE(F2:F6) -> 0.322 | G7: =AVERAGE(G2:G6) -> 0.54 | H7: =AVERAGE(H2:H6) -> 36.4025 | I7: =AVERAGE(I2:I6) -> 13.6125 | ... AG7: =AVERAGE(AG2:AG6) -> 300
A8: Std | B8: =STDEV(B2:B6) -> 0.10802777 | C8: =STDEV(C2:C6) -> #DIV/0! | D8: =STDEV(D2:D6) -> 0.44525274 | E8: =STDEV(E2:E6) -> 0.65872604 | F8: =STDEV(F2:F6) -> 0.13553597 | G8: =STDEV(G2:G6) -> 0.018708287 | H8: =STDEV(H2:H6) -> 0.086554414 | I8: =STDEV(I2:I6) -> 0.28146936 | ... AG8: =STDEV(AG2:AG6) -> 0
A10: Code 2 | B10: 国标重量 | C10: 厚度 | D10: 国标第一次吸收时间 | E10: 国标第二次吸收时间 | F10: 国标回渗 | G10: 国标渗漏 | H10: Cradle 重量 | I10: Cradle 1st intake | J10: Cradle 2nd intake | K10: Cradle 3rd intake | L10: Cradle扩散长度 | M10: L-H Weight | N10: L intake time | O10: L Rewet | P10: L Residue | Q10: H intake time | R10: H Rewet | S10: H Residue | T10: L-H 扩散长度 | U10: Weight after intake | V10: =V1 -> Surface Moisture重量 | W10: =W1 -> Surface Moisture吸收时间 | X10: =X1 -> Surface Moisture回渗 | Y10: =Y1 -> Run off | Z10: FTFE 1st intake time | AA10: FIFE leakage | AB10: FTFE 2st intake time | AC10: FIFE leakage | AD10: FTFE Rewet | AE10: FTFE 3st intake time | AF10: FIFE leakage | AG10: Pad Integrity
A11: 1 | B11: 35.8 | D11: 26.42 | E11: 26.69 | F11: 0.59 | G11: 0.46 | H11: 35.61 | I11: 14.12 | J11: 10.14 | K11: 34.66 | L11: 198 | M11: 35.53 | N11: 6.87 | O11: 0.15 | P11: 0.04 | Q11: 14.75 | R11: 0.24 | S11: 0.01 | T11: 330.5 | U11: 201.27 | V11: 36.52 | W11: 16.31 | X11: 0.16 | Y11: 0.7 | Z11: 16.58 | AA11: 0 | AB11: 8.45 | AC11: 0 | AD11: 11.38 | AE11: 5.66 | AF11: 0 | AG11: 160
A12: 2 | B12: 35.92 | D12: 24.88 | E12: 24.93 | F12: 0.51 | G12: 0.5 | H12: 35.91 | I12: 12.87 | J12: 10.56 | K12: 33.69 | L12: 193 | M12: 35.69 | N12: 7.85 | O12: 0.15 | P12: 0.06 | Q12: 17.65 | R12: 0.24 | S12: 0.01 | T12: 318.5 | U12: 201.58 | V12: 36.08 | W12: 14.56 | X12: 0.19 | Y12: 0 | Z12: 17.2 | AA12: 0 | AB12: 8.09 | AC12: 0 | AD12: 12.36 | AE12: 5.95 | AF12: 0 | AG12: 249
A13: 3 | B13: 35.42 | D13: 25.44 | E13: 26.17 | F13: 0.47 | G13: 0.54 | H13: 35.62 | I13: 13.44 | J13: 10.94 | K13: 33.44 | L13: 190 | M13: 35.6 | N13: 6.91 | O13: 0.18 | P13: 0.04 | Q13: 16.15 | R13: 0.26 | S13: 0.01 | T13: 316.5 | U13: 203.12 | V13: 36.31 | W13: 16.13 | X13: 0.18 | Y13: 0.55 | Z13: 16.54 | AA13: 0 | AB13: 7.96 | AC13: 0 | AD13: 9.76 | AE13: 5.02 | AF13: 0 | AG13: 174
A14: 4 | B14: 35.48 | D14: 23.77 | E14: 24.65 | F14: 0.32 | G14: 0.55 | H14: 35.29 | I14: 14.28 | J14: 11.23 | K14: 31.03 | L14: 204 | M14: 35.57 | N14: 8.44 | O14: 0.17 | P14: 0.01 | Q14: 14.84 | R14: 0.29 | S14: 0.03 | T14: 318 | U14: 203.02 | V14: 36.43 | W14: 14.72 | X14: 0.17 | Y14: 0.46 | Z14: 13.68 | AA14: 0 | AB14: 7.38 | AC14: 0 | AD14: 12.3 | AE14: 6.03 | AF14: 0 | AG14: 136
A15: 5 | B15: 35.49 | D15: 24.45 | E15: 26.48 | F15: 0.31 | G15: 0.54 | V15: 35.95 | W15: 15.5 | X15: 0.17 | Y15: 0 | AG15: 153
A16: adv | B16: =AVERAGE(B11:B15) -> 35.622 | C16: =AVERAGE(C11:C15) -> #DIV/0! | D16: =AVERAGE(D11:D15) -> 24.992 | E16: =AVERAGE(E11:E15) -> 25.784 | F16: =AVERAGE(F11:F15) -> 0.44 | G16: =AVERAGE(G11:G15) -> 0.518 | H16: =AVERAGE(H11:H15) -> 35.6075 | I16: =AVERAGE(I11:I15) -> 13.6775 | ... AG16: =AVERAGE(AG11:AG15) -> 174.4
A17: Std | B17: =STDEV(B11:B15) -> 0.22297982 | C17: =STDEV(C11:C15) -> #DIV/0! | D17: =STDEV(D11:D15) -> 1.0049229 | E17: =STDEV(E11:E15) -> 0.93133238 | F17: =STDEV(F11:F15) -> 0.12206556 | G17: =STDEV(G11:G15) -> 0.037682887 | H17: =STDEV(H11:H15) -> 0.25329495 | I17: =STDEV(I11:I15) -> 0.64994231 | ... AG17: =STDEV(AG11:AG15) -> 43.889634
A19: Control 1 | B19: 国标重量 | C19: 厚度 | D19: 国标第一次吸收时间 | E19: 国标第二次吸收时间 | F19: 国标回渗 | G19: 国标渗漏 | H19: Cradle 重量 | I19: Cradle 1st intake | J19: Cradle 2nd intake | K19: Cradle 3rd intake | L19: Cradle扩散长度 | M19: L-H Weight | N19: L intake time | O19: L Rewet | P19: L Residue | Q19: H intake time | R19: H Rewet | S19: H Residue | T19: L-H 扩散长度 | U19: Weight after intake | V19: =V10 -> Surface Moisture重量 | W19: =W10 -> Surface Moisture吸收时间 | X19: =X10 -> Surface Moisture回渗 | Y19: =Y10 -> Run off | Z19: FTFE 1st intake time | AA19: FIFE leakage | AB19: FTFE 2st intake time | AC19: FIFE leakage | AD19: FTFE Rewet | AE19: FTFE 3st intake time | AF19: FIFE leakage | AG19: Pad Integrity
A20: 1 | B20: 36.11 | D20: 26.04 | E20: 28.48 | F20: 0.13 | G20: 0.47 | H20: 36.39 | I20: 14.16 | J20: 11.47 | K20: 30.21 | L20: 201 | M20: 35.97 | N20: 7.6 | O20: 0.17 | P20: 0.14 | Q20: 15.06 | R20: 0.29 | S20: 0.05 | T20: 341.5 | U20: 201.85 | V20: 35.84 | W20: 16.13 | X20: 0.15 | Y20: 0.74 | Z20: 14.97 | AA20: 0 | AB20: 7.87 | AC20: 0 | AD20: 12.23 | AE20: 5.48 | AF20: 0 | AG20: 230
A21: 2 | B21: 36.26 | D21: 26.22 | E21: 29.4 | F21: 0.38 | G21: 0.49 | H21: 36.24 | I21: 14.47 | J21: 9.75 | K21: 28.84 | L21: 200 | M21: 36.05 | N21: 7.47 | O21: 0.19 | P21: 0.09 | Q21: 16.34 | R21: 0.29 | S21: 0.09 | T21: 330.5 | U21: 203 | V21: 36.37 | W21: 16.62 | X21: 0.19 | Y21: 0 | Z21: 16.88 | AA21: 0 | AB21: 8.18 | AC21: 0 | AD21: 14.05 | AE21: 5.96 | AF21: 0 | AG21: 213
A22: 3 | B22: 36.12 | D22: 24.57 | E22: 28.45 | F22: 0.52 | G22: 0.54 | H22: 35.85 | I22: 13.81 | J22: 11.88 | K22: 34.75 | L22: 212 | M22: 36.42 | N22: 9.28 | O22: 0.14 | P22: 0.04 | Q22: 13.48 | R22: 0.29 | S22: 0.05 | T22: 331.5 | U22: 201.98 | V22: 36.23 | W22: 15.41 | X22: 0.16 | Y22: 0.28 | Z22: 15.62 | AA22: 0 | AB22: 7.87 | AC22: 0 | AD22: 14.42 | AE22: 5.77 | AF22: 0 | AG22: 219
A23: 4 | B23: 35.85 | D23: 24.54 | E23: 28.82 | F23: 0.35 | G23: 0.53 | H23: 35.76 | I23: 15.13 | J23: 10.85 | K23: 36.11 | L23: 203 | M23: 35.95 | N23: 8.25 | O23: 0.19 | P23: 0.08 | Q23: 15.09 | R23: 0.29 | S23: 0.05 | T23: 327 | U23: 202.56 | V23: 36.47 | W23: 15.93 | X23: 0.16 | Y23: 0.11 | Z23: 18.3 | AA23: 0 | AB23: 8.6 | AC23: 0 | AD23: 15.01 | AE23: 6.05 | AF23: 0 | AG23: 300
A24: 5 | B24: 36.17 | D24: 23.92 | E24: 26.4 | F24: 0.48 | G24: 0.54 | V24: 36.4 | W24: 15.87 | X24: 0.17 | Y24: 0 | AG24: 226
A25: adv | B25: =AVERAGE(B20:B24) -> 36.102 | C25: =AVERAGE(C20:C24) -> #DIV/0! | D25: =AVERAGE(D20:D24) -> 25.058 | E25: =AVERAGE(E20:E24) -> 28.31 | F25: =AVERAGE(F20:F24) -> 0.372 | G25: =AVERAGE(G20:G24) -> 0.514 | H25: =AVERAGE(H20:H24) -> 36.06 | I25: =AVERAGE(I20:I24) -> 14.3925 | ... AG25: =AVERAGE(AG20:AG24) -> 237.6
A26: Std | B26: =STDEV(B20:B24) -> 0.1528725 | C26: =STDEV(C20:C24) -> #DIV/0! | D26: =STDEV(D20:D24) -> 1.0144062 | E26: =STDEV(E20:E24) -> 1.1341076 | F26: =STDEV(F20:F24) -> 0.15221695 | G26: =STDEV(G20:G24) -> 0.032093613 | H26: =STDEV(H20:H24) -> 0.30298515 | I26: =STDEV(I20:I24) -> 0.56073612 | ... AG26: =STDEV(AG20:AG24) -> 35.486617
A28: Control 2 | B28: 国标重量 | C28: 厚度 | D28: 国标第一次吸收时间 | E28: 国标第二次吸收时间 | F28: 国标回渗 | G28: 国标渗漏 | H28: Cradle 重量 | I28: Cradle 1st intake | J28: Cradle 2nd intake | K28: Cradle 3rd intake | L28: Cradle扩散长度 | M28: L-H Weight | N28: L intake time | O28: L Rewet | P28: L Residue | Q28: H intake time | R28: H Rewet | S28: H Residue | T28: L-H 扩散长度 | U28: Weight after intake | V28: Surface Moisture重量 | W28: Surface Moisture吸收时间 | X28: Surface Moisture回渗 | Y28: Run off | Z28: FTFE 1st intake time | AA28: FIFE leakage | AB28: FTFE 2st intake time | AC28: FIFE leakage | AD28: FTFE Rewet | AE28: FTFE 3st intake time | AF28: FIFE leakage | AG28: Pad Integrity
A29: 1 | B29: 36.64 | D29: 27.77 | E29: 29.48 | F29: 0.41 | G29: 0.46 | H29: 36.48 | I29: 14.35 | J29: 10.22 | K29: 38.22 | L29: 205 | M29: 36.39 | N29: 8.59 | O29: 0.19 | P29: 0.08 | Q29: 13.91 | R29: 0.3 | S29: 0.05 | T29: 324 | U29: 203.02 | V29: 36.05 | W29: 16.93 | X29: 0.17 | Y29: 0.36 | Z29: 15.2 | AA29: 0 | AB29: 8 | AC29: 0 | AD29: 11.82 | AE29: 5.66 | AF29: 0 | AG29: 300
A30: 2 | B30: 36.55 | D30: 26.14 | E30: 29.45 | F30: 0.53 | G30: 0.49 | H30: 36.3 | I30: 15 | J30: 11.37 | K30: 37.88 | L30: 203 | M30: 36.44 | N30: 6.39 | O30: 0.19 | P30: 0.09 | Q30: 14.94 | R30: 0.32 | S30: 0.03 | T30: 331.5 | U30: 203.58 | V30: 36.3 | W30: 18.72 | X30: 0.17 | Y30: 0.86 | Z30: 18.22 | AA30: 0 | AB30: 7.71 | AC30: 0 | AD30: 15.02 | AE30: 5.91 | AF30: 0 | AG30: 300
A31: 3 | B31: 36.13 | D31: 25.53 | E31: 28.64 | F31: 0.8 | G31: 0.51 | H31: 36.21 | I31: 14.53 | J31: 11.47 | K31: 40.82 | L31: 201 | M31: 36.6 | N31: 8.28 | O31: 0.21 | P31: 0.12 | Q31: 13.94 | R31: 0.33 | S31: 0.07 | T31: 344 | U31: 203.58 | V31: 36.4 | W31: 17.44 | X31: 0.16 | Y31: 0.1 | Z31: 17.17 | AA31: 0 | AB31: 7.94 | AC31: 0 | AD31: 13.71 | AE31: 5.8 | AF31: 0 | AG31: 300
A32: 4 | B32: 36.46 | D32: 25.68 | E32: 29.32 | F32: 0.19 | G32: 0.36 | H32: 36.26 | I32: 14.53 | J32: 10.81 | K32: 41.81 | L32: 211 | M32: 36.55 | N32: 7.81 | O32: 0.19 | P32: 0.11 | Q32: 15.93 | R32: 0.34 | S32: 0.07 | T32: 324.5 | U32: 203.19 | V32: 36.82 | W32: 18.5 | X32: 0.18 | Y32: 0.1 | Z32: 17.6 | AA32: 0 | AB32: 8.15 | AC32: 0 | AD32: 12.29 | AE32: 5.89 | AF32: 0 | AG32: 300
A33: 5 | B33: 36.76 | D33: 23.2 | E33: 26.48 | F33: 0.53 | G33: 0.51 | V33: 36 | W33: 16.63 | X33: 0.17 | Y33: 0.34 | AG33: 300
A34: adv | B34: =AVERAGE(B29:B33) -> 36.508 | C34: =AVERAGE(C29:C33) -> #DIV/0! | D34: =AVERAGE(D29:D33) -> 25.664 | E34: =AVERAGE(E29:E33) -> 28.674 | F34: =AVERAGE(F29:F33) -> 0.492 | G34: =AVERAGE(G29:G33) -> 0.466 | H34: =AVERAGE(H29:H33) -> 36.3125 | I34: =AVERAGE(I29:I33) -> 14.6025 | ... AG34: =AVERAGE(AG29:AG33) -> 300
A35: Std | B35: =STDEV(B29:B33) -> 0.23868389 | C35: =STDEV(C29:C33) -> #DIV/0! | D35: =STDEV(D29:D33) -> 1.6394603 | E35: =STDEV(E29:E33) -> 1.2731771 | F35: =STDEV(F29:F33) -> 0.22117866 | G35: =STDEV(G29:G33) -> 0.062689712 | H35: =STDEV(H29:H33) -> 0.11757976 | I35: =STDEV(I29:I33) -> 0.27825348 | ... AG35: =STDEV(AG29:AG33) -> 0
A37: Code 3 | B37: 国标重量 | C37: 厚度 | D37: 国标第一次吸收时间 | E37: 国标第二次吸收时间 | F37: 国标回渗 | G37: 国标渗漏 | H37: Cradle 重量 | I37: Cradle 1st intake | J37: Cradle 2nd intake | K37: Cradle 3rd intake | L37: Cradle扩散长度 | M37: L-H Weight | N37: L intake time | O37: L Rewet | P37: L Residue | Q37: H intake time | R37: H Rewet | S37: H Residue | T37: L-H 扩散长度 | U37: Weight after intake | Z37: FTFE 1st intake time | AA37: FIFE leakage | AB37: FTFE 2st intake time | AC37: FIFE leakage | AD37: FTFE Rewet | AE37: FTFE 3st intake time | AF37: FIFE leakage | AG37: Pad Integrity
A38: 1 | B38: 36.96 | D38: 27.9 | E38: 27.38 | F38: 0.87 | G38: 0.41 | H38: 37.17 | I38: 15.59 | J38: 13.82 | K38: 52.8 | L38: 244 | M38: 37.1 | N38: 10.66 | O38: 0.11 | P38: 0.02 | Q38: 15.09 | R38: 0.35 | S38: 0 | T38: 351 | U38: 205.22 | Z38: 16.98 | AA38: 0 | AB38: 8.22 | AC38: 0 | AD38: 13.03 | AE38: 5.46 | AF38: 0
A39: 2 | B39: 37.09 | D39: 27.82 | E39: 29.43 | F39: 1.01 | G39: 0.44 | H39: 36.85 | I39: 16.47 | J39: 14.37 | K39: 53.81 | L39: 241 | M39: 37.03 | N39: 11.09 | O39: 0.17 | P39: 0.01 | Q39: 16.28 | R39: 0.3 | S39: 0 | T39: 343 | U39: 203.12 | Z39: 15.2 | AA39: 0 | AB39: 7.74 | AC39: 0 | AD39: 13.32 | AE39: 5.37 | AF39: 0
A40: 3 | B40: 36.6 | D40: 25.38 | E40: 27.89 | F40: 1.19 | G40: 0.48 | H40: 37.41 | I40: 16.59 | J40: 14.19 | K40: 55.25 | L40: 243 | M40: 36.67 | N40: 10 | O40: 0.15 | P40: 0 | Q40: 15.68 | R40: 0.29 | S40: 0 | T40: 350 | U40: 202.6 | Z40: 16.12 | AA40: 0 | AB40: 7.95 | AC40: 0 | AD40: 10.47 | AE40: 5.11 | AF40: 0
A41: 4 | B41: 37.13 | D41: 26.24 | E41: 27.2 | F41: 0.87 | G41: 0.48 | H41: 36.75 | I41: 15.75 | J41: 16.22 | K41: 49.53 | L41: 243 | M41: 36.83 | N41: 9.69 | O41: 0.15 | P41: 0.01 | Q41: 16.91 | R41: 0.32 | S41: 0 | T41: 353 | U41: 205.11 | Z41: 13.37 | AA41: 0 | AB41: 8.03 | AC41: 0 | AD41: 12.79 | AE41: 5.22 | AF41: 0
A42: 5 | B42: 37.22 | D42: 25.23 | E42: 28.33 | F42: 1.01 | G42: 0.49 | H42: 37 | I42: 16.5 | J42: 16.18 | K42: 55.4 | L42: 237
A43: adv | B43: =AVERAGE(B38:B42) -> 37 | C43: =AVERAGE(C38:C42) -> #DIV/0! | D43: =AVERAGE(D38:D42) -> 26.514 | E43: =AVERAGE(E38:E42) -> 28.046 | F43: =AVERAGE(F38:F42) -> 0.99 | G43: =AVERAGE(G38:G42) -> 0.46 | H43: =AVERAGE(H38:H42) -> 37.036 | I43: =AVERAGE(I38:I42) -> 16.18 | ... U43: =AVERAGE(U38:U42) -> 204.0125 | Z43: =AVERAGE(Z38:Z42) -> 15.4175 | AA43: =AVERAGE(AA38:AA42) -> 0 | AB43: =AVERAGE(AB38:AB42) -> 7.985 | AC43: =AVERAGE(AC38:AC42) -> 0 | AD43: =AVERAGE(AD38:AD42) -> 12.4025 | AE43: =AVERAGE(AE38:AE42) -> 5.29 | AF43: =AVERAGE(AF38:AF42) -> 0
A44: Std | B44: =STDEV(B38:B42) -> 0.24238399 | C44: =STDEV(C38:C42) -> #DIV/0! | D44: =STDEV(D38:D42) -> 1.2880528 | E44: =STDEV(E38:E42) -> 0.89158847 | F44: =STDEV(F38:F42) -> 0.13190906 | G44: =STDEV(G38:G42) -> 0.03391165 | H44: =STDEV(H38:H42) -> 0.26245 | I44: =STDEV(I38:I42) -> 0.47106263 | ... U44: =STDEV(U38:U42) -> 1.3483663 | Z44: =STDEV(Z38:Z42) -> 1.5464448 | AA44: =STDEV(AA38:AA42) -> 0 | AB44: =STDEV(AB38:AB42) -> 0.19874607 | AC44: =STDEV(AC38:AC42) -> 0 | AD44: =STDEV(AD38:AD42) -> 1.3064296 | AE44: =STDEV(AE38:AE42) -> 0.15556349 | AF44: =STDEV(AF38:AF42) -> 0
...

Sheet Target Weight
B2: 110 pad | C2: SAP NO. | D2: Description | E2: RMS | F2: 数量 | G2: 重量
B3: LSN | C3: 14126684 | D3: NWOV TEXTILE SPL LSN 38g200mm WJ NB/S | E3: RMS 646 | F3: 1托盘 | G3: =38*200/1000*5000*4/1000 -> 152 | H3: kg
B4: PSN | C4: 14126435 | D4: NWOV TEXTILE SPL PSN 26g130mm WJ M+ | E4: RMS 602 | F4: 1托盘 | G4: =26*130/1000*5000*4/1000 -> 67.6 | H4: kg
B5: REL | C5: 14120936 | D5: NWOV TEXTILE TABCW 40g*115mm | E5: RMS 564 | F5: 1托盘 | G5: =40*115/1000*5000*4/1000 -> 92 | H5: kg
B6: SAM | C6: 14122367 | D6: SAM NR 511 Nuoer | E6: RMS 567 | F6: 1托盘 | G6: 800 | H6: kg
B7: Adh. | C7: 14112526 | D7: ADH CONSTRUCT HOT MELT BOX | E7: RMS 416 | F7: 1托盘 | G7: 20 | H7: kg
B9: 135 PAD
B10: PSN | C10: 14122674 | D10: NWOV TEXTILE PSN 26gsm * 155mm
B11: REL | D11: 大源寄送
B13: Support Layer | C13: 14123038 | D13: NWOV TEXTILE Support Layer 12g*165mm
B14: Liner | C14: 14130047 | D14: NWOV TEXTILE Naxos 2.0 D L 51gsm*490mm | F14: 供应商寄送
I15: 胶量2*4 | J15: Code 11 | K15: Code 13 | L15: Code 14
B16: Weight 135 PAD | C16: LSN | D16: 200 | F16: 38 | G16: 382 | H16: =G16*F16*D16/1000000 -> 2.9032 | I16: =H16 -> 2.9032 | J16: =I16/38*20 -> 1.528 | K16: =H16 -> 2.9032 | L16: =H16 -> 2.9032
B17: 135 | C17: PSN | D17: 155 | F17: 26 | G17: 382 | H17: =G17*F17*D17/1000000 -> 1.53946 | I17: =H17 -> 1.53946 | J17: =I17 -> 1.53946 | K17: =H17/26*20 -> 1.1842 | L17: =H17 -> 1.53946
C18: REL | D18: 140 | F18: 40 | G18: 382 | H18: =G18*F18*D18/1000000 -> 2.1392 | I18: =H18 -> 2.1392 | J18: =I18 -> 2.1392 | K18: =H18 -> 2.1392 | L18: =H18/40*28 -> 1.49744
C19: adh | D19: 137.5 | F19: 14 | G19: 382 | H19: =G19*F19*D19/1000000 -> 0.73535 | I19: =H19/14*8 -> 0.4202 | J19: =H19 -> 0.73535 | K19: =H19 -> 0.73535 | L19: =H19 -> 0.73535
C20: SAM | H20: 15.5 | I20: 15.5 | J20: 15.5 | K20: 15.5 | L20: =H20 -> 15.5
G21: Total | H21: =SUM(H16:H20) -> 22.81721 | I21: =SUM(I16:I20) -> 22.50206 | J21: =SUM(J16:J20) -> 21.44201 | K21: =SUM(K16:K20) -> 22.46195 | L21: =SUM(L16:L20) -> 22.17545
G22: LSL | H22: =H21*(1-5%) -> 21.67635 | I22: =I21*(1-5%) -> 21.376957 | J22: =J21*(1-5%) -> 20.369909 | K22: =K21*(1-5%) -> 21.338853 | L22: =L21*(1-5%) -> 21.066677
G23: USL | H23: =H21*(1+5%) -> 23.958071 | I23: =I21*(1+5%) -> 23.627163 | J23: =J21*(1+5%) -> 22.514111 | K23: =K21*(1+5%) -> 23.585048 | L23: =L21*(1+5%) -> 23.284222
B26: Weight 110 PAD | C26: LSN | D26: 200 | F26: 38 | G26: 382 | H26: =G26*F26*D26/1000000 -> 2.9032
C27: PSN | D27: 130 | F27: 26 | G27: 382 | H27: =G27*F27*D27/1000000 -> 1.29116
C28: REL | D28: 115 | F28: 40 | G28: 382 | H28: =G28*F28*D28/1000000 -> 1.7572
C29: adh | D29: 125 | F29: 14 | G29: 382 | H29: =G29*F29*D29/1000000 -> 0.6685
C30: SAM | H30: =7.75*2 -> 15.5
G31: Total | H31: =SUM(H26:H30) -> 22.12006
G32: LSL | H32: =H31*(1-5%) -> 21.014057
G33: USL | H33: =H31*(1+5%) -> 23.226063
H45: =H21+0.5 -> 23.31721

Sheet Material List
A1: I. Full Core Material List (Including Topsheet) v3.0
A2: No. | B2: Material Name | C2: Specification/Model | D2: Applicable Layer/Structural Position | E2: Estimated Usage/Quantity | F2: Supplier Candidates/Reference Price | G2: ETA
A3: 1 | B3: Code 1: 50gsm 上层：25gsm，10% 三叶草截面纤维 (KC 提供)，90% 2D Bico PE/PET (延江提供) 下层：25gsm，50% 三叶草截面纤维（KC 提供），50% 4D Bico PE/PET(延江提供) | C3: Width: 102mm Length: >100m Cookie:3" core, roll diameter ≤700mm | D3: Liner (Tianjin) | E3: >100m | F3: Yanjan | G3: 18th Sep | H3: 21号可完成
A4: 2 | B4: Code 2-A: 30 gsm (优先) 上层：15gsm，10% 三叶草截面纤维 (KC 提供)，90% 2D Bico PE/PET (延江提供) 下层：15gsm，50% 三叶草截面纤维（KC 提供），50% 4D Bico PE/PET (延江提供) | C4: Width: 82mm Length: 6km Spooling: 3" core, core length ≤ 600mm, roll diameter ≤700mm Cookie:3" core, roll diameter ≤700mm | D4: Liner (Chunayue) | E4: 6km | F4: Yanjan | G4: 18th Sep | H4: 未到货
A5: 3 | B5: Code 2-B: 30 gsm (取决于异型纤维的量) 上层：15gsm，100% 2D Bico PE/PET (延江提供) 下层：15gsm，50% 三叶草截面纤维（KC 提供），50% 4D Bico PE/PET (延江提供) | C5: Width: 82mm Length: 6km Spooling: 3" core, core length ≤ 600mm, roll diameter ≤700mm Cookie:3" core, roll diameter ≤700mm | D5: Liner (Chunayue) | E5: 6km | F5: Yanjan | G5: 18th Sep | H5: 不测试
A6: 4 | B6: 上层：11.2gsm 80% 2D PE/PET 38MM (KET-221F)20% 3D PE/PET 38MM (KET-1A1F) 下层：16.8gsm 50% 3.5D 中空 PE/PET 51mm (KET-P14KF5)40% PTT/PET s-s 7D 51mm 10% PVA 6D 51mm | C6: Width:145mm Length: 300m Cookie:3" core | D6: REL | E6: 6 rolls | F6: Minrui | G6: 18th Sep | H6: 21号可完成
A7: 5 | B7: Nuoer 610s | C7: / | D7: SAP | E7: 300kg | F7: Nuoer | G7: 18th Sep
A8: 6 | B8: Nuoer 950 | C8: / | D8: SAP | E8: 300kg | F8: Nuoer | G8: 18th Sep
A9: 7 | B9: Nuoer High GBP trial code | C9: / | D9: SAP | E9: 20kg | F9: Nuoer | G9: 18th Sep
A10: 8 | B10: Nuoer 50% 610+ 50% 511 | C10: /
A11: 9 | B11: Nuoer 50% 610+ 50% 950 | C11: /
A12: 10 | B12: 20gsm PP+fluff | C12: Width: 200mm Length: 2km Cookie: 6.75" core, roll diameter ≤800mm | D12: LSN | E12: 2km | F12: Unikorn | G12: Arrived | H12: 上次测试完成
A13: 11 | B13: 20gsm PP+fluff | C13: Width: 155mm Length: 2km Cookie: 6.75" core, roll diameter ≤800mm | D13: PSN | E13: 2km | F13: Unikorn | G13: Arrived
A14: 12 | B14: TBD 含三叶草粘胶纤维 | C14: Width: 82mm Length: 6km Spooling: 3" core, core length ≤ 600mm, roll diameter ≤700mm Cookie:3" core, roll diameter ≤700mm | D14: LSN | E14: 3 rolls | F14: Wangjin | G14: 20th Sep | H14: 21号可完成
A15: 13 | B15: 亲水胶 3059 | E15: 80kg | F15: Henkel | G15: Arrived
